Traceback (most recent call last):
  File "/Users/rajdeep_ch/opt/anaconda3/lib/python3.9/site-packages/jupyter_cache/executors/utils.py", line 51, in single_nb_execution
    executenb(
  File "/Users/rajdeep_ch/opt/anaconda3/lib/python3.9/site-packages/nbclient/client.py", line 1204, in execute
    return NotebookClient(nb=nb, resources=resources, km=km, **kwargs).execute()
  File "/Users/rajdeep_ch/opt/anaconda3/lib/python3.9/site-packages/nbclient/util.py", line 84, in wrapped
    return just_run(coro(*args, **kwargs))
  File "/Users/rajdeep_ch/opt/anaconda3/lib/python3.9/site-packages/nbclient/util.py", line 62, in just_run
    return loop.run_until_complete(coro)
  File "/Users/rajdeep_ch/opt/anaconda3/lib/python3.9/asyncio/base_events.py", line 647, in run_until_complete
    return future.result()
  File "/Users/rajdeep_ch/opt/anaconda3/lib/python3.9/site-packages/nbclient/client.py", line 663, in async_execute
    await self.async_execute_cell(
  File "/Users/rajdeep_ch/opt/anaconda3/lib/python3.9/site-packages/nbclient/client.py", line 965, in async_execute_cell
    await self._check_raise_for_error(cell, cell_index, exec_reply)
  File "/Users/rajdeep_ch/opt/anaconda3/lib/python3.9/site-packages/nbclient/client.py", line 862, in _check_raise_for_error
    raise CellExecutionError.from_cell_and_msg(cell, exec_reply_content)
nbclient.exceptions.CellExecutionError: An error occurred while executing the following cell:
------------------
myimage = generate_from_frequencies(file_contents)
plt.figure(figsize=(20,10))
plt.imshow(myimage, interpolation = 'nearest')
plt.axis('off')

print("Run 1")
print("The Beatles - Lucy in the Sky With Diamonds")

plt.show()
------------------

[0;31m---------------------------------------------------------------------------[0m
[0;31mNameError[0m                                 Traceback (most recent call last)
Input [0;32mIn [6][0m, in [0;36m<cell line: 1>[0;34m()[0m
[0;32m----> 1[0m myimage [38;5;241m=[39m generate_from_frequencies([43mfile_contents[49m)
[1;32m      2[0m plt[38;5;241m.[39mfigure(figsize[38;5;241m=[39m([38;5;241m20[39m,[38;5;241m10[39m))
[1;32m      3[0m plt[38;5;241m.[39mimshow(myimage, interpolation [38;5;241m=[39m [38;5;124m'[39m[38;5;124mnearest[39m[38;5;124m'[39m)

[0;31mNameError[0m: name 'file_contents' is not defined
NameError: name 'file_contents' is not defined

